Workbook

Sheet Pivot Table
A3: Row Labels | B3: Sum of Order Value (₹) | C3: Count of PO ID
A4: Bearings and Mechanical | B4: 0.20058787 | C4: 24
A5: Cleaning and Consumables | B5: 0.093232099 | C5: 18
A6: Electricals | B6: 0.26911708 | C6: 24
A7: Hand Tools | B7: 0.0976851 | C7: 18
A8: Safety and PPE | B8: 0.33937786 | C8: 36
A9: Grand Total | B9: 1 | C9: 120
A10: Key Finding: Safety and PPE is the top category with ₹2,97,69,140 (~33.9% of total spend).
A13: Row Labels | B13: Average of Delivery Days | C13: Count of PO ID | D13: Average of Delay Days
A14: East | B14: 14.433333 | C14: 30 | D14: 4.8333333
A15: North | B15: 10.633333 | C15: 30 | D15: 2.7666667
A16: South | B16: 10.9 | C16: 30 | D16: 2.6
A17: West | B17: 11.066667 | C17: 30 | D17: 3.1333333
A18: Grand Total | B18: 11.758333 | C18: 120 | D18: 3.3333333
A19: The East region shows the weakest performance, with the highest average delivery time (14 days), highest average delay (5 days).
A20: Category | B20: Safety and PPE
A22: Row Labels | B22: Average of Unit Price (₹) | C22: Sum of Order Value (₹) | D22: Average of Delay Days | E22: Average of Defect Rate
A23: S001 | B23: 436.3675 | C23: 7006928 | D23: 2.75 | E23: 0.027503168
A24: Bharat Industrial Supplies | B24: 436.3675 | C24: 7006928 | D24: 2.75 | E24: 0.027503168
A25: S003 | B25: 544.09429 | C25: 6086705.5 | D25: 0.57142857 | E25: 0.0064911164
A26: SafePro India | B26: 544.09429 | C26: 6086705.5 | D26: 0.57142857 | E26: 0.0064911164
A27: S008 | B27: 431.60556 | C27: 6974370.5 | D27: 4.3333333 | E27: 0.064793092
A28: Metro Industrial Mart | B28: 431.60556 | C28: 6974370.5 | D28: 4.3333333 | E28: 0.064793092
A29: S009 | B29: 399.4975 | C29: 2623357.5 | D29: 1.5 | E29: 0.011041652
A30: SecureTech Safety Solutions | B30: 399.4975 | C30: 2623357.5 | D30: 1.5 | E30: 0.011041652
A31: S012 | B31: 527.265 | C31: 7077778.5 | D31: 3.375 | E31: 0.03452732
A32: ProServe MRO Solutions | B32: 527.265 | C32: 7077778.5 | D32: 3.375 | E32: 0.03452732
A33: Grand Total | B33: 472.22667 | C33: 29769140 | D33: 2.7222222 | E33: 0.032471838

Sheet 06_Assignment_Answers
A1: Moglix Procurement Analysis — Assignment Answers
A2: Answers to all 10 assignment questions, cross-referenced to the calculations on the other sheets of this workbook
A4: Business task: Moglix management wants to improve procurement performance without unnecessarily increasing cost. This sheet uses the completed 01_Purchase_Orders, 02_Supplier_Master, 03_Product_Master, 04_Rates_and_Rules and 05_Sourcing_Decision sheets to locate the most important problem, evaluate the suppliers involved, and recommend how the next major purchase should be handled.
A8: Stage 1 — Locate the Procurement Problem
A9: Q1 | B9: Calculate the value of each order and the number of days taken to deliver it.
B10: Order Value and Delivery Days are calculated for every one of the 120 purchase orders directly in 01_Purchase_Orders (columns P and Q), using row-level formulas so the sheet recalculates automatically: • Order Value (₹) = Qty Ordered × Unit Price (₹) • Delivery Days = Delivery Date − Order Date • Delay Days = MAX(0, Delivery Date − Promised Date) • Defect Rate = Rejected Qty ÷ Qty Received Portfolio-wide totals (live from 01_Purchase_Orders):
B11: Metric | C11: Value
B12: Total orders | C12: 120
B13: Total order value (₹) | C13: =SUM(PurchaseOrdersTable[[#All],[Order Value (₹)]]) -> 87716800
B14: Average order value (₹) | C14: =AVERAGE(PurchaseOrdersTable[[#All],[Order Value (₹)]]) -> 730973.34
B15: Average delivery time (days) | C15: =AVERAGE(PurchaseOrdersTable[[#All],[Delivery Days]]) -> 11.758333
B16: Answer: Order Value and Delivery Days are computed for every PO in 01_Purchase_Orders; on average an order is worth roughly ₹7.3 lakh and takes about 12 days to arrive — the starting point for the delivery-problem investigation below.
A18: Q2 | B18: Which product category accounts for the largest share of procurement spending? Report the category and the total amount spent on it.
B19: Category | C19: Total Spend (₹) | D19: Orders | E19: Avg Unit Price (₹)
B20: =INDEX([1]!CategoryAnalysisWorkspace[Category],1) -> Safety and PPE | C20: =SUMIF(PurchaseOrdersTable[[#All],[Category]],'06_Assignment_Answers'!B20,PurchaseOrdersTable[[#All],[Order Value (₹)]]) -> 29769140 | D20: =COUNTIF(PurchaseOrdersTable[[#All],[Category]],'06_Assignment_Answers'!B20) -> 36 | E20: =AVERAGEIF(PurchaseOrdersTable[[#All],[Category]],'06_Assignment_Answers'!B20,PurchaseOrdersTable[[#All],[Unit Price (₹)]]) -> 472.22667
B21: =INDEX([1]!CategoryAnalysisWorkspace[Category],2) -> Electricals | C21: =SUMIF(PurchaseOrdersTable[[#All],[Category]],'06_Assignment_Answers'!B21,PurchaseOrdersTable[[#All],[Order Value (₹)]]) -> 23606089 | D21: =COUNTIF(PurchaseOrdersTable[[#All],[Category]],'06_Assignment_Answers'!B21) -> 24 | E21: =AVERAGEIF(PurchaseOrdersTable[[#All],[Category]],'06_Assignment_Answers'!B21,PurchaseOrdersTable[[#All],[Unit Price (₹)]]) -> 2222.4504
B22: =INDEX([1]!CategoryAnalysisWorkspace[Category],3) -> Hand Tools | C22: =SUMIF(PurchaseOrdersTable[[#All],[Category]],'06_Assignment_Answers'!B22,PurchaseOrdersTable[[#All],[Order Value (₹)]]) -> 8568624.4 | D22: =COUNTIF(PurchaseOrdersTable[[#All],[Category]],'06_Assignment_Answers'!B22) -> 18 | E22: =AVERAGEIF(PurchaseOrdersTable[[#All],[Category]],'06_Assignment_Answers'!B22,PurchaseOrdersTable[[#All],[Unit Price (₹)]]) -> 4883.2978
B23: =INDEX([1]!CategoryAnalysisWorkspace[Category],4) -> Bearings and Mechanical | C23: =SUMIF(PurchaseOrdersTable[[#All],[Category]],'06_Assignment_Answers'!B23,PurchaseOrdersTable[[#All],[Order Value (₹)]]) -> 17594926 | D23: =COUNTIF(PurchaseOrdersTable[[#All],[Category]],'06_Assignment_Answers'!B23) -> 24 | E23: =AVERAGEIF(PurchaseOrdersTable[[#All],[Category]],'06_Assignment_Answers'!B23,PurchaseOrdersTable[[#All],[Unit Price (₹)]]) -> 1858.1862
B24: =INDEX([1]!CategoryAnalysisWorkspace[Category],5) -> Cleaning and Consumables | C24: =SUMIF(PurchaseOrdersTable[[#All],[Category]],'06_Assignment_Answers'!B24,PurchaseOrdersTable[[#All],[Order Value (₹)]]) -> 8178021.4 | D24: =COUNTIF(PurchaseOrdersTable[[#All],[Category]],'06_Assignment_Answers'!B24) -> 18 | E24: =AVERAGEIF(PurchaseOrdersTable[[#All],[Category]],'06_Assignment_Answers'!B24,PurchaseOrdersTable[[#All],[Unit Price (₹)]]) -> 2343.6672
B26: =CONCATENATE("Answer: ", INDEX([1]!CategoryAnalysisWorkspace[Category],MATCH(MAX([1]!CategoryAnalysisWorkspace[Total Spend]),[1]!CategoryAnalysisWorkspace[Total Spend],0))," is the largest spend category at ₹", TEXT(MAX([1]!CategoryAnalysisWorkspace[Total Spend]),"#,##0")," (", TEXT(MAX([1]!CategoryAnalysisWorkspace[Total Spend])/SUM([1]!CategoryAnalysisWorkspace[Total Spend]),"0.0%"),") of total procurement spend, driven by high order volume even though it has the lowest average unit price of any category.") -> Answer: Safety and PPE is the largest spend category at ₹2,97,69,140 (33.9%) of total procurement spend, driven by high order volume even though it has the lowest average unit price of any category.
A28: Q3 | B28: Which region shows the weakest delivery performance? Consider both the number of delayed orders and the average delivery time.
B29: Region | C29: Avg. Delivery Days | D29: Avg. Delay Days | E29: Seriously Late Orders
B30: North | C30: =AVERAGEIF(PurchaseOrdersTable[[#All],[Region]],'06_Assignment_Answers'!B30,PurchaseOrdersTable[[#All],[Delivery Days]]) -> 10.633333 | D30: =AVERAGEIF(PurchaseOrdersTable[[#All],[Region]],'06_Assignment_Answers'!B30,PurchaseOrdersTable[[#All],[Delay Days]]) -> 2.7666667 | E30: =COUNTIFS(PurchaseOrdersTable[[#All],[Region]],'06_Assignment_Answers'!B30,PurchaseOrdersTable[[#All],[Delivery Status]],"Seriously late") -> 9
B31: West | C31: =AVERAGEIF(PurchaseOrdersTable[[#All],[Region]],'06_Assignment_Answers'!B31,PurchaseOrdersTable[[#All],[Delivery Days]]) -> 11.066667 | D31: =AVERAGEIF(PurchaseOrdersTable[[#All],[Region]],'06_Assignment_Answers'!B31,PurchaseOrdersTable[[#All],[Delay Days]]) -> 3.1333333 | E31: =COUNTIFS(PurchaseOrdersTable[[#All],[Region]],'06_Assignment_Answers'!B31,PurchaseOrdersTable[[#All],[Delivery Status]],"Seriously late") -> 10
B32: South | C32: =AVERAGEIF(PurchaseOrdersTable[[#All],[Region]],'06_Assignment_Answers'!B32,PurchaseOrdersTable[[#All],[Delivery Days]]) -> 10.9 | D32: =AVERAGEIF(PurchaseOrdersTable[[#All],[Region]],'06_Assignment_Answers'!B32,PurchaseOrdersTable[[#All],[Delay Days]]) -> 2.6 | E32: =COUNTIFS(PurchaseOrdersTable[[#All],[Region]],'06_Assignment_Answers'!B32,PurchaseOrdersTable[[#All],[Delivery Status]],"Seriously late") -> 10
B33: East | C33: =AVERAGEIF(PurchaseOrdersTable[[#All],[Region]],'06_Assignment_Answers'!B33,PurchaseOrdersTable[[#All],[Delivery Days]]) -> 14.433333 | D33: =AVERAGEIF(PurchaseOrdersTable[[#All],[Region]],'06_Assignment_Answers'!B33,PurchaseOrdersTable[[#All],[Delay Days]]) -> 4.8333333 | E33: =COUNTIFS(PurchaseOrdersTable[[#All],[Region]],'06_Assignment_Answers'!B33,PurchaseOrdersTable[[#All],[Delivery Status]],"Seriously late") -> 21
B35: =CONCATENATE("Answer: ", INDEX(B30:B33,MATCH(MAX(D30:D33),D30:D33,0)), " shows the weakest delivery performance, with the highest average delivery time and the highest average delay of all four regions, and the largest share of Seriously Late orders.") -> Answer: East shows the weakest delivery performance, with the highest average delivery time and the highest average delay of all four regions, and the largest share of Seriously Late orders.
A37: Stage 2 — Evaluate the Suppliers (focus: Safety and PPE)
A38: Q4 | B38: Within the category identified in Q2, which suppliers handle the largest value of orders?
B39: Supplier (in Safety & PPE) | C39: Order Value (₹) | D39: Orders
B40: =VLOOKUP("S001",[1]!SupplierMasterTable[#All],2,) -> Bharat Industrial Supplies | C40: =SUMIFS(PurchaseOrdersTable[[#All],[Order Value (₹)]],PurchaseOrdersTable[[#All],[Supplier Code]],"S001",PurchaseOrdersTable[[#All],[Category]],"Safety and PPE") -> 7006928 | D40: =COUNTIFS(PurchaseOrdersTable[[#All],[Supplier Code]],"S001",PurchaseOrdersTable[[#All],[Category]],"Safety and PPE") -> 8
B41: =VLOOKUP("S003",[1]!SupplierMasterTable[#All],2,) -> SafePro India | C41: =SUMIFS(PurchaseOrdersTable[[#All],[Order Value (₹)]],PurchaseOrdersTable[[#All],[Supplier Code]],"S003",PurchaseOrdersTable[[#All],[Category]],"Safety and PPE") -> 6086705.5 | D41: =COUNTIFS(PurchaseOrdersTable[[#All],[Supplier Code]],"S003",PurchaseOrdersTable[[#All],[Category]],"Safety and PPE") -> 7
B42: =VLOOKUP("S008",[1]!SupplierMasterTable[#All],2,) -> Metro Industrial Mart | C42: =SUMIFS(PurchaseOrdersTable[[#All],[Order Value (₹)]],PurchaseOrdersTable[[#All],[Supplier Code]],"S008",PurchaseOrdersTable[[#All],[Category]],"Safety and PPE") -> 6974370.5 | D42: =COUNTIFS(PurchaseOrdersTable[[#All],[Supplier Code]],"S008",PurchaseOrdersTable[[#All],[Category]],"Safety and PPE") -> 9
B43: =VLOOKUP("S009",[1]!SupplierMasterTable[#All],2,) -> SecureTech Safety Solutions | C43: =SUMIFS(PurchaseOrdersTable[[#All],[Order Value (₹)]],PurchaseOrdersTable[[#All],[Supplier Code]],"S009",PurchaseOrdersTable[[#All],[Category]],"Safety and PPE") -> 2623357.5 | D43: =COUNTIFS(PurchaseOrdersTable[[#All],[Supplier Code]],"S009",PurchaseOrdersTable[[#All],[Category]],"Safety and PPE") -> 4
B44: =VLOOKUP("S012",[1]!SupplierMasterTable[#All],2,) -> ProServe MRO Solutions | C44: =SUMIFS(PurchaseOrdersTable[[#All],[Order Value (₹)]],PurchaseOrdersTable[[#All],[Supplier Code]],"S012",PurchaseOrdersTable[[#All],[Category]],"Safety and PPE") -> 7077778.5 | D44: =COUNTIFS(PurchaseOrdersTable[[#All],[Supplier Code]],"S012",PurchaseOrdersTable[[#All],[Category]],"Safety and PPE") -> 8
B46: Answer: ProServe MRO Solutions, Bharat Industrial Supplies and Metro Industrial Mart handle the largest — and very similar — value of Safety & PPE orders (each roughly ₹70 lakh, ~23-24% of category spend). SafePro India is close behind (~20%); SecureTech Safety Solutions is a smaller, occasional supplier (~9%). These five are compared in Q5.
A48: Q5 | B48: Compare these suppliers on unit price, delivery performance and defect rate. What trade-offs do you observe?
B49: Supplier | C49: Avg. Unit Price (₹) | D49: On-Time % | E49: Avg. Delay (days) | F49: Avg. Defect Rate
B50: =VLOOKUP("S001",[1]!SupplierMasterTable[#All],2,) -> Bharat Industrial Supplies | C50: =AVERAGEIFS(PurchaseOrdersTable[[#All],[Unit Price (₹)]],PurchaseOrdersTable[[#All],[Supplier Code]],"S001",PurchaseOrdersTable[[#All],[Category]],"Safety and PPE") -> 436.3675 | D50: =COUNTIFS(PurchaseOrdersTable[[#All],[Supplier Code]],"S001",PurchaseOrdersTable[[#All],[Category]],"Safety and PPE",PurchaseOrdersTable[[#All],[Delivery Status]],"On time")/COUNTIFS(PurchaseOrdersTable[[#All],[Supplier Code]],"S001",PurchaseOrdersTable[[#All],[Category]],"Safety and PPE") -> 0.125 | E50: =AVERAGEIFS(PurchaseOrdersTable[[#All],[Delay Days]],PurchaseOrdersTable[[#All],[Supplier Code]],"S001",PurchaseOrdersTable[[#All],[Category]],"Safety and PPE") -> 2.75 | F50: =AVERAGEIFS(PurchaseOrdersTable[[#All],[Defect Rate]],PurchaseOrdersTable[[#All],[Supplier Code]],"S001",PurchaseOrdersTable[[#All],[Category]],"Safety and PPE") -> 0.027503168
B51: =VLOOKUP("S003",[1]!SupplierMasterTable[#All],2,) -> SafePro India | C51: =AVERAGEIFS(PurchaseOrdersTable[[#All],[Unit Price (₹)]],PurchaseOrdersTable[[#All],[Supplier Code]],"S003",PurchaseOrdersTable[[#All],[Category]],"Safety and PPE") -> 544.09429 | D51: =COUNTIFS(PurchaseOrdersTable[[#All],[Supplier Code]],"S003",PurchaseOrdersTable[[#All],[Category]],"Safety and PPE",PurchaseOrdersTable[[#All],[Delivery Status]],"On time")/COUNTIFS(PurchaseOrdersTable[[#All],[Supplier Code]],"S003",PurchaseOrdersTable[[#All],[Category]],"Safety and PPE") -> 0.57142857 | E51: =AVERAGEIFS(PurchaseOrdersTable[[#All],[Delay Days]],PurchaseOrdersTable[[#All],[Supplier Code]],"S003",PurchaseOrdersTable[[#All],[Category]],"Safety and PPE") -> 0.57142857 | F51: =AVERAGEIFS(PurchaseOrdersTable[[#All],[Defect Rate]],PurchaseOrdersTable[[#All],[Supplier Code]],"S003",PurchaseOrdersTable[[#All],[Category]],"Safety and PPE") -> 0.0064911164
...

Sheet 01_Purchase_Orders
A1: Moglix Procurement Analysis Assignment | Purchase Orders | V1: STUDENT INSTRUCTIONS
A2: Simulated classroom data inspired by the Moglix case. These are not actual Moglix operational records.
V3: 1. Use Supplier Code and Product Code to retrieve the missing names and category. 2. Calculate Order Value, Delivery Days, Delay Days and Defect Rate. 3. Create a Delivery Status rule using the thresholds on 04_Rates_and_Rules. 4. Use this completed table for your category, region and supplier analysis. 5. Create any Pivot Table or chart on a new worksheet so that this raw-data sheet remains unchanged. Important: Do not type supplier names or categories manually. Use lookup formulas.
A4: PO ID | B4: Order Date | C4: Promised Date | D4: Delivery Date | E4: Region | F4: Supplier Code | G4: Product Code | H4: Qty Ordered | I4: Qty Received | J4: Rejected Qty | K4: Unit Price (₹) | L4: Purchase Type | M4: Supplier Name | N4: Product Name | O4: Category | P4: Order Value (₹) | Q4: Delivery Days | R4: Delay Days | S4: Defect Rate | T4: Delivery Status
A5: PO001 | B5: 46188 | C5: 46197 | D5: 46199 | E5: North | F5: S012 | G5: PPE-004 | H5: 950 | I5: 934 | J5: 38 | K5: 533.18 | L5: Routine | M5: =VLOOKUP(PurchaseOrdersTable[[#This Row],[Supplier Code]],SupplierMasterTable[[Supplier Code]:[Supplier Name]],2,) -> ProServe MRO Solutions | N5: =VLOOKUP(PurchaseOrdersTable[[#This Row],[Product Code]],ProductMasterTable[[Product Code]:[Product Name]],2,) -> Reflective Safety Jacket | O5: =VLOOKUP(PurchaseOrdersTable[[#This Row],[Product Code]],ProductMasterTable[[#All],[Product Code]:[Category]],3,) -> Safety and PPE | P5: =PurchaseOrdersTable[[#This Row],[Qty Ordered]]*PurchaseOrdersTable[[#This Row],[Unit Price (₹)]] -> 506521 | Q5: =PurchaseOrdersTable[[#This Row],[Delivery Date]]-PurchaseOrdersTable[[#This Row],[Order Date]] -> 11 | R5: =MAX(0, PurchaseOrdersTable[[#This Row],[Delivery Date]]-PurchaseOrdersTable[[#This Row],[Promised Date]]) -> 2 | S5: =PurchaseOrdersTable[[#This Row],[Rejected Qty]]/PurchaseOrdersTable[[#This Row],[Qty Received]] -> 0.040685225 | T5: =IF(PurchaseOrdersTable[[#This Row],[Delay Days]]<=0,"On time", IF(PurchaseOrdersTable[[#This Row],[Delay Days]]<=3,"Slightly delay", IF(PurchaseOrdersTable[[#This Row],[Delay Days]]>3,"Seriously late"))) -> Slightly delay
A6: PO002 | B6: 46191 | C6: 46202 | D6: 46200 | E6: West | F6: S007 | G6: BRG-003 | H6: 280 | I6: 280 | J6: 12 | K6: 1484.78 | L6: Routine | M6: =VLOOKUP(PurchaseOrdersTable[[#This Row],[Supplier Code]],SupplierMasterTable[[Supplier Code]:[Supplier Name]],2,) -> National Bearings Company | N6: =VLOOKUP(PurchaseOrdersTable[[#This Row],[Product Code]],ProductMasterTable[[Product Code]:[Product Name]],2,) -> Heavy-Duty Industrial Belt | O6: =VLOOKUP(PurchaseOrdersTable[[#This Row],[Product Code]],ProductMasterTable[[#All],[Product Code]:[Category]],3,) -> Bearings and Mechanical | P6: =PurchaseOrdersTable[[#This Row],[Qty Ordered]]*PurchaseOrdersTable[[#This Row],[Unit Price (₹)]] -> 415738.4 | Q6: =PurchaseOrdersTable[[#This Row],[Delivery Date]]-PurchaseOrdersTable[[#This Row],[Order Date]] -> 9 | R6: =MAX(0, PurchaseOrdersTable[[#This Row],[Delivery Date]]-PurchaseOrdersTable[[#This Row],[Promised Date]]) -> 0 | S6: =PurchaseOrdersTable[[#This Row],[Rejected Qty]]/PurchaseOrdersTable[[#This Row],[Qty Received]] -> 0.042857143 | T6: =IF(PurchaseOrdersTable[[#This Row],[Delay Days]]<=0,"On time", IF(PurchaseOrdersTable[[#This Row],[Delay Days]]<=3,"Slightly delay", IF(PurchaseOrdersTable[[#This Row],[Delay Days]]>3,"Seriously late"))) -> On time
A7: PO003 | B7: 46190 | C7: 46198 | D7: 46198 | E7: South | F7: S002 | G7: ELE-003 | H7: 700 | I7: 691 | J7: 9 | K7: 2262.63 | L7: Routine | M7: =VLOOKUP(PurchaseOrdersTable[[#This Row],[Supplier Code]],SupplierMasterTable[[Supplier Code]:[Supplier Name]],2,) -> Western MRO Hub | N7: =VLOOKUP(PurchaseOrdersTable[[#This Row],[Product Code]],ProductMasterTable[[Product Code]:[Product Name]],2,) -> Three-Phase Contactor | O7: =VLOOKUP(PurchaseOrdersTable[[#This Row],[Product Code]],ProductMasterTable[[#All],[Product Code]:[Category]],3,) -> Electricals | P7: =PurchaseOrdersTable[[#This Row],[Qty Ordered]]*PurchaseOrdersTable[[#This Row],[Unit Price (₹)]] -> 1583841 | Q7: =PurchaseOrdersTable[[#This Row],[Delivery Date]]-PurchaseOrdersTable[[#This Row],[Order Date]] -> 8 | R7: =MAX(0, PurchaseOrdersTable[[#This Row],[Delivery Date]]-PurchaseOrdersTable[[#This Row],[Promised Date]]) -> 0 | S7: =PurchaseOrdersTable[[#This Row],[Rejected Qty]]/PurchaseOrdersTable[[#This Row],[Qty Received]] -> 0.013024602 | T7: =IF(PurchaseOrdersTable[[#This Row],[Delay Days]]<=0,"On time", IF(PurchaseOrdersTable[[#This Row],[Delay Days]]<=3,"Slightly delay", IF(PurchaseOrdersTable[[#This Row],[Delay Days]]>3,"Seriously late"))) -> On time
A8: PO004 | B8: 46076 | C8: 46086 | D8: 46088 | E8: East | F8: S001 | G8: PPE-001 | H8: 1800 | I8: 1793 | J8: 48 | K8: 412.14 | L8: Routine | M8: =VLOOKUP(PurchaseOrdersTable[[#This Row],[Supplier Code]],SupplierMasterTable[[Supplier Code]:[Supplier Name]],2,) -> Bharat Industrial Supplies | N8: =VLOOKUP(PurchaseOrdersTable[[#This Row],[Product Code]],ProductMasterTable[[Product Code]:[Product Name]],2,) -> Industrial Safety Helmet | O8: =VLOOKUP(PurchaseOrdersTable[[#This Row],[Product Code]],ProductMasterTable[[#All],[Product Code]:[Category]],3,) -> Safety and PPE | P8: =PurchaseOrdersTable[[#This Row],[Qty Ordered]]*PurchaseOrdersTable[[#This Row],[Unit Price (₹)]] -> 741852 | Q8: =PurchaseOrdersTable[[#This Row],[Delivery Date]]-PurchaseOrdersTable[[#This Row],[Order Date]] -> 12 | R8: =MAX(0, PurchaseOrdersTable[[#This Row],[Delivery Date]]-PurchaseOrdersTable[[#This Row],[Promised Date]]) -> 2 | S8: =PurchaseOrdersTable[[#This Row],[Rejected Qty]]/PurchaseOrdersTable[[#This Row],[Qty Received]] -> 0.026770775 | T8: =IF(PurchaseOrdersTable[[#This Row],[Delay Days]]<=0,"On time", IF(PurchaseOrdersTable[[#This Row],[Delay Days]]<=3,"Slightly delay", IF(PurchaseOrdersTable[[#This Row],[Delay Days]]>3,"Seriously late"))) -> Slightly delay
A9: PO005 | B9: 46184 | C9: 46191 | D9: 46193 | E9: North | F9: S003 | G9: PPE-002 | H9: 900 | I9: 900 | J9: 3 | K9: 796.23 | L9: Routine | M9: =VLOOKUP(PurchaseOrdersTable[[#This Row],[Supplier Code]],SupplierMasterTable[[Supplier Code]:[Supplier Name]],2,) -> SafePro India | N9: =VLOOKUP(PurchaseOrdersTable[[#This Row],[Product Code]],ProductMasterTable[[Product Code]:[Product Name]],2,) -> Nitrile Gloves - Box of 100 | O9: =VLOOKUP(PurchaseOrdersTable[[#This Row],[Product Code]],ProductMasterTable[[#All],[Product Code]:[Category]],3,) -> Safety and PPE | P9: =PurchaseOrdersTable[[#This Row],[Qty Ordered]]*PurchaseOrdersTable[[#This Row],[Unit Price (₹)]] -> 716607 | Q9: =PurchaseOrdersTable[[#This Row],[Delivery Date]]-PurchaseOrdersTable[[#This Row],[Order Date]] -> 9 | R9: =MAX(0, PurchaseOrdersTable[[#This Row],[Delivery Date]]-PurchaseOrdersTable[[#This Row],[Promised Date]]) -> 2 | S9: =PurchaseOrdersTable[[#This Row],[Rejected Qty]]/PurchaseOrdersTable[[#This Row],[Qty Received]] -> 0.0033333333 | T9: =IF(PurchaseOrdersTable[[#This Row],[Delay Days]]<=0,"On time", IF(PurchaseOrdersTable[[#This Row],[Delay Days]]<=3,"Slightly delay", IF(PurchaseOrdersTable[[#This Row],[Delay Days]]>3,"Seriously late"))) -> Slightly delay
A10: PO006 | B10: 46165 | C10: 46177 | D10: 46187 | E10: West | F10: S004 | G10: ELE-004 | H10: 320 | I10: 314 | J10: 11 | K10: 1728.27 | L10: Routine | M10: =VLOOKUP(PurchaseOrdersTable[[#This Row],[Supplier Code]],SupplierMasterTable[[Supplier Code]:[Supplier Name]],2,) -> Eastern Engineering Traders | N10: =VLOOKUP(PurchaseOrdersTable[[#This Row],[Product Code]],ProductMasterTable[[Product Code]:[Product Name]],2,) -> Industrial LED High-Bay Light | O10: =VLOOKUP(PurchaseOrdersTable[[#This Row],[Product Code]],ProductMasterTable[[#All],[Product Code]:[Category]],3,) -> Electricals | P10: =PurchaseOrdersTable[[#This Row],[Qty Ordered]]*PurchaseOrdersTable[[#This Row],[Unit Price (₹)]] -> 553046.4 | Q10: =PurchaseOrdersTable[[#This Row],[Delivery Date]]-PurchaseOrdersTable[[#This Row],[Order Date]] -> 22 | R10: =MAX(0, PurchaseOrdersTable[[#This Row],[Delivery Date]]-PurchaseOrdersTable[[#This Row],[Promised Date]]) -> 10 | S10: =PurchaseOrdersTable[[#This Row],[Rejected Qty]]/PurchaseOrdersTable[[#This Row],[Qty Received]] -> 0.035031847 | T10: =IF(PurchaseOrdersTable[[#This Row],[Delay Days]]<=0,"On time", IF(PurchaseOrdersTable[[#This Row],[Delay Days]]<=3,"Slightly delay", IF(PurchaseOrdersTable[[#This Row],[Delay Days]]>3,"Seriously late"))) -> Seriously late
A11: PO007 | B11: 46156 | C11: 46165 | D11: 46168 | E11: South | F11: S012 | G11: TOOL-002 | H11: 70 | I11: 70 | J11: 1 | K11: 4661.53 | L11: Routine | M11: =VLOOKUP(PurchaseOrdersTable[[#This Row],[Supplier Code]],SupplierMasterTable[[Supplier Code]:[Supplier Name]],2,) -> ProServe MRO Solutions | N11: =VLOOKUP(PurchaseOrdersTable[[#This Row],[Product Code]],ProductMasterTable[[Product Code]:[Product Name]],2,) -> Industrial Torque Wrench | O11: =VLOOKUP(PurchaseOrdersTable[[#This Row],[Product Code]],ProductMasterTable[[#All],[Product Code]:[Category]],3,) -> Hand Tools | P11: =PurchaseOrdersTable[[#This Row],[Qty Ordered]]*PurchaseOrdersTable[[#This Row],[Unit Price (₹)]] -> 326307.1 | Q11: =PurchaseOrdersTable[[#This Row],[Delivery Date]]-PurchaseOrdersTable[[#This Row],[Order Date]] -> 12 | R11: =MAX(0, PurchaseOrdersTable[[#This Row],[Delivery Date]]-PurchaseOrdersTable[[#This Row],[Promised Date]]) -> 3 | S11: =PurchaseOrdersTable[[#This Row],[Rejected Qty]]/PurchaseOrdersTable[[#This Row],[Qty Received]] -> 0.014285714 | T11: =IF(PurchaseOrdersTable[[#This Row],[Delay Days]]<=0,"On time", IF(PurchaseOrdersTable[[#This Row],[Delay Days]]<=3,"Slightly delay", IF(PurchaseOrdersTable[[#This Row],[Delay Days]]>3,"Seriously late"))) -> Slightly delay
A12: PO008 | B12: 46086 | C12: 46095 | D12: 46099 | E12: East | F12: S012 | G12: TOOL-001 | H12: 70 | I12: 69 | J12: 1 | K12: 3798.16 | L12: Routine | M12: =VLOOKUP(PurchaseOrdersTable[[#This Row],[Supplier Code]],SupplierMasterTable[[Supplier Code]:[Supplier Name]],2,) -> ProServe MRO Solutions | N12: =VLOOKUP(PurchaseOrdersTable[[#This Row],[Product Code]],ProductMasterTable[[Product Code]:[Product Name]],2,) -> Industrial Angle Grinder | O12: =VLOOKUP(PurchaseOrdersTable[[#This Row],[Product Code]],ProductMasterTable[[#All],[Product Code]:[Category]],3,) -> Hand Tools | P12: =PurchaseOrdersTable[[#This Row],[Qty Ordered]]*PurchaseOrdersTable[[#This Row],[Unit Price (₹)]] -> 265871.2 | Q12: =PurchaseOrdersTable[[#This Row],[Delivery Date]]-PurchaseOrdersTable[[#This Row],[Order Date]] -> 13 | R12: =MAX(0, PurchaseOrdersTable[[#This Row],[Delivery Date]]-PurchaseOrdersTable[[#This Row],[Promised Date]]) -> 4 | S12: =PurchaseOrdersTable[[#This Row],[Rejected Qty]]/PurchaseOrdersTable[[#This Row],[Qty Received]] -> 0.014492754 | T12: =IF(PurchaseOrdersTable[[#This Row],[Delay Days]]<=0,"On time", IF(PurchaseOrdersTable[[#This Row],[Delay Days]]<=3,"Slightly delay", IF(PurchaseOrdersTable[[#This Row],[Delay Days]]>3,"Seriously late"))) -> Seriously late
A13: PO009 | B13: 46046 | C13: 46055 | D13: 46057 | E13: North | F13: S012 | G13: ELE-004 | H13: 480 | I13: 479 | J13: 14 | K13: 1815.56 | L13: Routine | M13: =VLOOKUP(PurchaseOrdersTable[[#This Row],[Supplier Code]],SupplierMasterTable[[Supplier Code]:[Supplier Name]],2,) -> ProServe MRO Solutions | N13: =VLOOKUP(PurchaseOrdersTable[[#This Row],[Product Code]],ProductMasterTable[[Product Code]:[Product Name]],2,) -> Industrial LED High-Bay Light | O13: =VLOOKUP(PurchaseOrdersTable[[#This Row],[Product Code]],ProductMasterTable[[#All],[Product Code]:[Category]],3,) -> Electricals | P13: =PurchaseOrdersTable[[#This Row],[Qty Ordered]]*PurchaseOrdersTable[[#This Row],[Unit Price (₹)]] -> 871468.8 | Q13: =PurchaseOrdersTable[[#This Row],[Delivery Date]]-PurchaseOrdersTable[[#This Row],[Order Date]] -> 11 | R13: =MAX(0, PurchaseOrdersTable[[#This Row],[Delivery Date]]-PurchaseOrdersTable[[#This Row],[Promised Date]]) -> 2 | S13: =PurchaseOrdersTable[[#This Row],[Rejected Qty]]/PurchaseOrdersTable[[#This Row],[Qty Received]] -> 0.029227557 | T13: =IF(PurchaseOrdersTable[[#This Row],[Delay Days]]<=0,"On time", IF(PurchaseOrdersTable[[#This Row],[Delay Days]]<=3,"Slightly delay", IF(PurchaseOrdersTable[[#This Row],[Delay Days]]>3,"Seriously late"))) -> Slightly delay
A14: PO010 | B14: 46051 | C14: 46061 | D14: 46062 | E14: West | F14: S001 | G14: ELE-003 | H14: 260 | I14: 258 | J14: 8 | K14: 2112.32 | L14: Routine | M14: =VLOOKUP(PurchaseOrdersTable[[#This Row],[Supplier Code]],SupplierMasterTable[[Supplier Code]:[Supplier Name]],2,) -> Bharat Industrial Supplies | N14: =VLOOKUP(PurchaseOrdersTable[[#This Row],[Product Code]],ProductMasterTable[[Product Code]:[Product Name]],2,) -> Three-Phase Contactor | O14: =VLOOKUP(PurchaseOrdersTable[[#This Row],[Product Code]],ProductMasterTable[[#All],[Product Code]:[Category]],3,) -> Electricals | P14: =PurchaseOrdersTable[[#This Row],[Qty Ordered]]*PurchaseOrdersTable[[#This Row],[Unit Price (₹)]] -> 549203.2 | Q14: =PurchaseOrdersTable[[#This Row],[Delivery Date]]-PurchaseOrdersTable[[#This Row],[Order Date]] -> 11 | R14: =MAX(0, PurchaseOrdersTable[[#This Row],[Delivery Date]]-PurchaseOrdersTable[[#This Row],[Promised Date]]) -> 1 | S14: =PurchaseOrdersTable[[#This Row],[Rejected Qty]]/PurchaseOrdersTable[[#This Row],[Qty Received]] -> 0.031007752 | T14: =IF(PurchaseOrdersTable[[#This Row],[Delay Days]]<=0,"On time", IF(PurchaseOrdersTable[[#This Row],[Delay Days]]<=3,"Slightly delay", IF(PurchaseOrdersTable[[#This Row],[Delay Days]]>3,"Seriously late"))) -> Slightly delay
A15: PO011 | B15: 46148 | C15: 46161 | D15: 46167 | E15: South | F15: S011 | G15: BRG-002 | H15: 530 | I15: 518 | J15: 32 | K15: 2703.64 | L15: Routine | M15: =VLOOKUP(PurchaseOrdersTable[[#This Row],[Supplier Code]],SupplierMasterTable[[Supplier Code]:[Supplier Name]],2,) -> Eastline Components | N15: =VLOOKUP(PurchaseOrdersTable[[#This Row],[Product Code]],ProductMasterTable[[Product Code]:[Product Name]],2,) -> Industrial Roller Bearing | O15: =VLOOKUP(PurchaseOrdersTable[[#This Row],[Product Code]],ProductMasterTable[[#All],[Product Code]:[Category]],3,) -> Bearings and Mechanical | P15: =PurchaseOrdersTable[[#This Row],[Qty Ordered]]*PurchaseOrdersTable[[#This Row],[Unit Price (₹)]] -> 1432929.2 | Q15: =PurchaseOrdersTable[[#This Row],[Delivery Date]]-PurchaseOrdersTable[[#This Row],[Order Date]] -> 19 | R15: =MAX(0, PurchaseOrdersTable[[#This Row],[Delivery Date]]-PurchaseOrdersTable[[#This Row],[Promised Date]]) -> 6 | S15: =PurchaseOrdersTable[[#This Row],[Rejected Qty]]/PurchaseOrdersTable[[#This Row],[Qty Received]] -> 0.061776062 | T15: =IF(PurchaseOrdersTable[[#This Row],[Delay Days]]<=0,"On time", IF(PurchaseOrdersTable[[#This Row],[Delay Days]]<=3,"Slightly delay", IF(PurchaseOrdersTable[[#This Row],[Delay Days]]>3,"Seriously late"))) -> Seriously late
A16: PO012 | B16: 46060 | C16: 46065 | D16: 46073 | E16: East | F16: S008 | G16: PPE-003 | H16: 1450 | I16: 1427 | J16: 75 | K16: 278.2 | L16: Routine | M16: =VLOOKUP(PurchaseOrdersTable[[#This Row],[Supplier Code]],SupplierMasterTable[[Supplier Code]:[Supplier Name]],2,) -> Metro Industrial Mart | N16: =VLOOKUP(PurchaseOrdersTable[[#This Row],[Product Code]],ProductMasterTable[[Product Code]:[Product Name]],2,) -> Safety Goggles | O16: =VLOOKUP(PurchaseOrdersTable[[#This Row],[Product Code]],ProductMasterTable[[#All],[Product Code]:[Category]],3,) -> Safety and PPE | P16: =PurchaseOrdersTable[[#This Row],[Qty Ordered]]*PurchaseOrdersTable[[#This Row],[Unit Price (₹)]] -> 403390 | Q16: =PurchaseOrdersTable[[#This Row],[Delivery Date]]-PurchaseOrdersTable[[#This Row],[Order Date]] -> 13 | R16: =MAX(0, PurchaseOrdersTable[[#This Row],[Delivery Date]]-PurchaseOrdersTable[[#This Row],[Promised Date]]) -> 8 | S16: =PurchaseOrdersTable[[#This Row],[Rejected Qty]]/PurchaseOrdersTable[[#This Row],[Qty Received]] -> 0.052557814 | T16: =IF(PurchaseOrdersTable[[#This Row],[Delay Days]]<=0,"On time", IF(PurchaseOrdersTable[[#This Row],[Delay Days]]<=3,"Slightly delay", IF(PurchaseOrdersTable[[#This Row],[Delay Days]]>3,"Seriously late"))) -> Seriously late
... A124: PO120 | B124: 46075 | C124: 46087 | D124: 46095 | E124: East | F124: S004 | G124: BRG-002 | H124: 420 | I124: 410 | J124: 16 | K124: 2785.58 | L124: Routine | M124: =VLOOKUP(PurchaseOrdersTable[[#This Row],[Supplier Code]],SupplierMasterTable[[Supplier Code]:[Supplier Name]],2,) -> Eastern Engineering Traders | N124: =VLOOKUP(PurchaseOrdersTable[[#This Row],[Product Code]],ProductMasterTable[[Product Code]:[Product Name]],2,) -> Industrial Roller Bearing | O124: =VLOOKUP(PurchaseOrdersTable[[#This Row],[Product Code]],ProductMasterTable[[#All],[Product Code]:[Category]],3,) -> Bearings and Mechanical | P124: =PurchaseOrdersTable[[#This Row],[Qty Ordered]]*PurchaseOrdersTable[[#This Row],[Unit Price (₹)]] -> 1169943.6 | Q124: =PurchaseOrdersTable[[#This Row],[Delivery Date]]-PurchaseOrdersTable[[#This Row],[Order Date]] -> 20 | R124: =MAX(0, PurchaseOrdersTable[[#This Row],[Delivery Date]]-PurchaseOrdersTable[[#This Row],[Promised Date]]) -> 8 | S124: =PurchaseOrdersTable[[#This Row],[Rejected Qty]]/PurchaseOrdersTable[[#This Row],[Qty Received]] -> 0.03902439 | T124: =IF(PurchaseOrdersTable[[#This Row],[Delay Days]]<=0,"On time", IF(PurchaseOrdersTable[[#This Row],[Delay Days]]<=3,"Slightly delay", IF(PurchaseOrdersTable[[#This Row],[Delay Days]]>3,"Seriously late"))) -> Seriously late

Sheet 02_Supplier_Master
A1: Supplier Master and Performance Workspace | J1: Supplier Performance Workspace | S1: HOW TO USE THIS SHEET
A2: Reference information is provided. Historical performance measures must be calculated from 01_Purchase_Orders.
S3: Master table (left): Use Supplier Code to retrieve supplier information. Performance workspace (centre): Summarise each supplier's historical performance using 01_Purchase_Orders. Recommended measures: • Total Order Value • Average Unit Price • Average Delay Days • On-Time Percentage • Average Defect Rate Use the classification rules on 04_Rates_and_Rules to label each supplier as Preferred, Acceptable or Needs Review.
A4: Supplier Code | B4: Supplier Name | C4: City | D4: Standard Lead Time | E4: Approval Status | F4: Certification | G4: Existing Rating | H4: Primary Categories | J4: Supplier Code | K4: Supplier Name | L4: Total Order Value | M4: Average Unit Price | N4: Average Delay Days | O4: On-Time % | P4: Average Defect Rate | Q4: Performance Class
A5: S001 | B5: Bharat Industrial Supplies | C5: Delhi | D5: 10 | E5: Approved | F5: ISO 9001 | G5: 4.1 | H5: Safety and PPE; Electricals | J5: S001 | K5: Bharat Industrial Supplies | L5: =SUMIF(PurchaseOrdersTable[[#All],[Supplier Code]],SupplierPerformanceWorkspace[[#This Row],[Supplier Code]],PurchaseOrdersTable[[#All],[Order Value (₹)]]) -> 12670799 | M5: =AVERAGEIF(PurchaseOrdersTable[[#All],[Supplier Code]],SupplierPerformanceWorkspace[[#This Row],[Supplier Code]],PurchaseOrdersTable[[#All],[Unit Price (₹)]]) -> 1168.1367 | N5: =AVERAGEIF(PurchaseOrdersTable[[#All],[Supplier Code]],SupplierPerformanceWorkspace[[#This Row],[Supplier Code]],PurchaseOrdersTable[[#All],[Delay Days]]) -> 3.3333333 | O5: =COUNTIFS(PurchaseOrdersTable[[#All],[Supplier Code]],SupplierPerformanceWorkspace[[#This Row],[Supplier Code]],PurchaseOrdersTable[[#All],[Delivery Status]], "On Time") /COUNTIF(PurchaseOrdersTable[[#All],[Supplier Code]],SupplierPerformanceWorkspace[[#This Row],[Supplier Code]]) -> 0.083333333 | P5: =AVERAGEIF(PurchaseOrdersTable[[#All],[Supplier Code]],SupplierPerformanceWorkspace[[#This Row],[Supplier Code]],PurchaseOrdersTable[[#All],[Defect Rate]]) -> 0.028282953 | Q5: =IF(AND(SupplierPerformanceWorkspace[[#This Row],[On-Time %]]>=0.9,SupplierPerformanceWorkspace[[#This Row],[Average Defect Rate]]<=0.02,SupplierPerformanceWorkspace[[#This Row],[Average Delay Days]]<=2), "Preferred", IF(AND(SupplierPerformanceWorkspace[[#This Row],[On-Time %]]>=0.75,SupplierPerformanceWorkspace[[#This Row],[Average Defect Rate]]<=0.05,SupplierPerformanceWorkspace[[#This Row],[Average Delay Days]]<=5), "Acceptable", "Needs Review")) -> Needs Review
A6: S002 | B6: Western MRO Hub | C6: Ahmedabad | D6: 8 | E6: Approved | F6: ISO 9001 | G6: 4.3 | H6: Electricals; Hand Tools | J6: S002 | K6: Western MRO Hub | L6: =SUMIF(PurchaseOrdersTable[[#All],[Supplier Code]],SupplierPerformanceWorkspace[[#This Row],[Supplier Code]],PurchaseOrdersTable[[#All],[Order Value (₹)]]) -> 8395919.6 | M6: =AVERAGEIF(PurchaseOrdersTable[[#All],[Supplier Code]],SupplierPerformanceWorkspace[[#This Row],[Supplier Code]],PurchaseOrdersTable[[#All],[Unit Price (₹)]]) -> 4347.4675 | N6: =AVERAGEIF(PurchaseOrdersTable[[#All],[Supplier Code]],SupplierPerformanceWorkspace[[#This Row],[Supplier Code]],PurchaseOrdersTable[[#All],[Delay Days]]) -> 1 | O6: =COUNTIFS(PurchaseOrdersTable[[#All],[Supplier Code]],SupplierPerformanceWorkspace[[#This Row],[Supplier Code]],PurchaseOrdersTable[[#All],[Delivery Status]], "On Time") /COUNTIF(PurchaseOrdersTable[[#All],[Supplier Code]],SupplierPerformanceWorkspace[[#This Row],[Supplier Code]]) -> 0.5 | P6: =AVERAGEIF(PurchaseOrdersTable[[#All],[Supplier Code]],SupplierPerformanceWorkspace[[#This Row],[Supplier Code]],PurchaseOrdersTable[[#All],[Defect Rate]]) -> 0.01327411 | Q6: =IF(AND(SupplierPerformanceWorkspace[[#This Row],[On-Time %]]>=0.9,SupplierPerformanceWorkspace[[#This Row],[Average Defect Rate]]<=0.02,SupplierPerformanceWorkspace[[#This Row],[Average Delay Days]]<=2), "Preferred", IF(AND(SupplierPerformanceWorkspace[[#This Row],[On-Time %]]>=0.75,SupplierPerformanceWorkspace[[#This Row],[Average Defect Rate]]<=0.05,SupplierPerformanceWorkspace[[#This Row],[Average Delay Days]]<=5), "Acceptable", "Needs Review")) -> Needs Review
A7: S003 | B7: SafePro India | C7: Noida | D7: 7 | E7: Approved | F7: ISO 45001 | G7: 4.5 | H7: Safety and PPE | J7: S003 | K7: SafePro India | L7: =SUMIF(PurchaseOrdersTable[[#All],[Supplier Code]],SupplierPerformanceWorkspace[[#This Row],[Supplier Code]],PurchaseOrdersTable[[#All],[Order Value (₹)]]) -> 6086705.5 | M7: =AVERAGEIF(PurchaseOrdersTable[[#All],[Supplier Code]],SupplierPerformanceWorkspace[[#This Row],[Supplier Code]],PurchaseOrdersTable[[#All],[Unit Price (₹)]]) -> 544.09429 | N7: =AVERAGEIF(PurchaseOrdersTable[[#All],[Supplier Code]],SupplierPerformanceWorkspace[[#This Row],[Supplier Code]],PurchaseOrdersTable[[#All],[Delay Days]]) -> 0.57142857 | O7: =COUNTIFS(PurchaseOrdersTable[[#All],[Supplier Code]],SupplierPerformanceWorkspace[[#This Row],[Supplier Code]],PurchaseOrdersTable[[#All],[Delivery Status]], "On Time") /COUNTIF(PurchaseOrdersTable[[#All],[Supplier Code]],SupplierPerformanceWorkspace[[#This Row],[Supplier Code]]) -> 0.57142857 | P7: =AVERAGEIF(PurchaseOrdersTable[[#All],[Supplier Code]],SupplierPerformanceWorkspace[[#This Row],[Supplier Code]],PurchaseOrdersTable[[#All],[Defect Rate]]) -> 0.0064911164 | Q7: =IF(AND(SupplierPerformanceWorkspace[[#This Row],[On-Time %]]>=0.9,SupplierPerformanceWorkspace[[#This Row],[Average Defect Rate]]<=0.02,SupplierPerformanceWorkspace[[#This Row],[Average Delay Days]]<=2), "Preferred", IF(AND(SupplierPerformanceWorkspace[[#This Row],[On-Time %]]>=0.75,SupplierPerformanceWorkspace[[#This Row],[Average Defect Rate]]<=0.05,SupplierPerformanceWorkspace[[#This Row],[Average Delay Days]]<=5), "Acceptable", "Needs Review")) -> Needs Review
A8: S004 | B8: Eastern Engineering Traders | C8: Kolkata | D8: 12 | E8: Conditional | F8: ISO 9001 | G8: 3.4 | H8: Bearings and Mechanical; Electricals | J8: S004 | K8: Eastern Engineering Traders | L8: =SUMIF(PurchaseOrdersTable[[#All],[Supplier Code]],SupplierPerformanceWorkspace[[#This Row],[Supplier Code]],PurchaseOrdersTable[[#All],[Order Value (₹)]]) -> 9263652.2 | M8: =AVERAGEIF(PurchaseOrdersTable[[#All],[Supplier Code]],SupplierPerformanceWorkspace[[#This Row],[Supplier Code]],PurchaseOrdersTable[[#All],[Unit Price (₹)]]) -> 1978.8655 | N8: =AVERAGEIF(PurchaseOrdersTable[[#All],[Supplier Code]],SupplierPerformanceWorkspace[[#This Row],[Supplier Code]],PurchaseOrdersTable[[#All],[Delay Days]]) -> 5.9090909 | O8: =COUNTIFS(PurchaseOrdersTable[[#All],[Supplier Code]],SupplierPerformanceWorkspace[[#This Row],[Supplier Code]],PurchaseOrdersTable[[#All],[Delivery Status]], "On Time") /COUNTIF(PurchaseOrdersTable[[#All],[Supplier Code]],SupplierPerformanceWorkspace[[#This Row],[Supplier Code]]) -> 0 | P8: =AVERAGEIF(PurchaseOrdersTable[[#All],[Supplier Code]],SupplierPerformanceWorkspace[[#This Row],[Supplier Code]],PurchaseOrdersTable[[#All],[Defect Rate]]) -> 0.051696944 | Q8: =IF(AND(SupplierPerformanceWorkspace[[#This Row],[On-Time %]]>=0.9,SupplierPerformanceWorkspace[[#This Row],[Average Defect Rate]]<=0.02,SupplierPerformanceWorkspace[[#This Row],[Average Delay Days]]<=2), "Preferred", IF(AND(SupplierPerformanceWorkspace[[#This Row],[On-Time %]]>=0.75,SupplierPerformanceWorkspace[[#This Row],[Average Defect Rate]]<=0.05,SupplierPerformanceWorkspace[[#This Row],[Average Delay Days]]<=5), "Acceptable", "Needs Review")) -> Needs Review
A9: S005 | B9: Vertex Electricals | C9: Pune | D9: 9 | E9: Approved | F9: ISO 9001; ISO 14001 | G9: 4.2 | H9: Electricals | J9: S005 | K9: Vertex Electricals | L9: =SUMIF(PurchaseOrdersTable[[#All],[Supplier Code]],SupplierPerformanceWorkspace[[#This Row],[Supplier Code]],PurchaseOrdersTable[[#All],[Order Value (₹)]]) -> 3207875.4 | M9: =AVERAGEIF(PurchaseOrdersTable[[#All],[Supplier Code]],SupplierPerformanceWorkspace[[#This Row],[Supplier Code]],PurchaseOrdersTable[[#All],[Unit Price (₹)]]) -> 1803.674 | N9: =AVERAGEIF(PurchaseOrdersTable[[#All],[Supplier Code]],SupplierPerformanceWorkspace[[#This Row],[Supplier Code]],PurchaseOrdersTable[[#All],[Delay Days]]) -> 1 | O9: =COUNTIFS(PurchaseOrdersTable[[#All],[Supplier Code]],SupplierPerformanceWorkspace[[#This Row],[Supplier Code]],PurchaseOrdersTable[[#All],[Delivery Status]], "On Time") /COUNTIF(PurchaseOrdersTable[[#All],[Supplier Code]],SupplierPerformanceWorkspace[[#This Row],[Supplier Code]]) -> 0.4 | P9: =AVERAGEIF(PurchaseOrdersTable[[#All],[Supplier Code]],SupplierPerformanceWorkspace[[#This Row],[Supplier Code]],PurchaseOrdersTable[[#All],[Defect Rate]]) -> 0.010892052 | Q9: =IF(AND(SupplierPerformanceWorkspace[[#This Row],[On-Time %]]>=0.9,SupplierPerformanceWorkspace[[#This Row],[Average Defect Rate]]<=0.02,SupplierPerformanceWorkspace[[#This Row],[Average Delay Days]]<=2), "Preferred", IF(AND(SupplierPerformanceWorkspace[[#This Row],[On-Time %]]>=0.75,SupplierPerformanceWorkspace[[#This Row],[Average Defect Rate]]<=0.05,SupplierPerformanceWorkspace[[#This Row],[Average Delay Days]]<=5), "Acceptable", "Needs Review")) -> Needs Review
A10: S006 | B10: Precision Tools India | C10: Bengaluru | D10: 6 | E10: Approved | F10: ISO 9001 | G10: 4.6 | H10: Hand Tools | J10: S006 | K10: Precision Tools India | L10: =SUMIF(PurchaseOrdersTable[[#All],[Supplier Code]],SupplierPerformanceWorkspace[[#This Row],[Supplier Code]],PurchaseOrdersTable[[#All],[Order Value (₹)]]) -> 1295676.1 | M10: =AVERAGEIF(PurchaseOrdersTable[[#All],[Supplier Code]],SupplierPerformanceWorkspace[[#This Row],[Supplier Code]],PurchaseOrdersTable[[#All],[Unit Price (₹)]]) -> 4792.52 | N10: =AVERAGEIF(PurchaseOrdersTable[[#All],[Supplier Code]],SupplierPerformanceWorkspace[[#This Row],[Supplier Code]],PurchaseOrdersTable[[#All],[Delay Days]]) -> 1.5 | O10: =COUNTIFS(PurchaseOrdersTable[[#All],[Supplier Code]],SupplierPerformanceWorkspace[[#This Row],[Supplier Code]],PurchaseOrdersTable[[#All],[Delivery Status]], "On Time") /COUNTIF(PurchaseOrdersTable[[#All],[Supplier Code]],SupplierPerformanceWorkspace[[#This Row],[Supplier Code]]) -> 0.25 | P10: =AVERAGEIF(PurchaseOrdersTable[[#All],[Supplier Code]],SupplierPerformanceWorkspace[[#This Row],[Supplier Code]],PurchaseOrdersTable[[#All],[Defect Rate]]) -> 0.012019231 | Q10: =IF(AND(SupplierPerformanceWorkspace[[#This Row],[On-Time %]]>=0.9,SupplierPerformanceWorkspace[[#This Row],[Average Defect Rate]]<=0.02,SupplierPerformanceWorkspace[[#This Row],[Average Delay Days]]<=2), "Preferred", IF(AND(SupplierPerformanceWorkspace[[#This Row],[On-Time %]]>=0.75,SupplierPerformanceWorkspace[[#This Row],[Average Defect Rate]]<=0.05,SupplierPerformanceWorkspace[[#This Row],[Average Delay Days]]<=5), "Acceptable", "Needs Review")) -> Needs Review
A11: S007 | B11: National Bearings Company | C11: Chennai | D11: 11 | E11: Approved | F11: ISO 9001 | G11: 4 | H11: Bearings and Mechanical | J11: S007 | K11: National Bearings Company | L11: =SUMIF(PurchaseOrdersTable[[#All],[Supplier Code]],SupplierPerformanceWorkspace[[#This Row],[Supplier Code]],PurchaseOrdersTable[[#All],[Order Value (₹)]]) -> 5472501.4 | M11: =AVERAGEIF(PurchaseOrdersTable[[#All],[Supplier Code]],SupplierPerformanceWorkspace[[#This Row],[Supplier Code]],PurchaseOrdersTable[[#All],[Unit Price (₹)]]) -> 1836.5171 | N11: =AVERAGEIF(PurchaseOrdersTable[[#All],[Supplier Code]],SupplierPerformanceWorkspace[[#This Row],[Supplier Code]],PurchaseOrdersTable[[#All],[Delay Days]]) -> 2.4285714 | O11: =COUNTIFS(PurchaseOrdersTable[[#All],[Supplier Code]],SupplierPerformanceWorkspace[[#This Row],[Supplier Code]],PurchaseOrdersTable[[#All],[Delivery Status]], "On Time") /COUNTIF(PurchaseOrdersTable[[#All],[Supplier Code]],SupplierPerformanceWorkspace[[#This Row],[Supplier Code]]) -> 0.28571429 | P11: =AVERAGEIF(PurchaseOrdersTable[[#All],[Supplier Code]],SupplierPerformanceWorkspace[[#This Row],[Supplier Code]],PurchaseOrdersTable[[#All],[Defect Rate]]) -> 0.017776547 | Q11: =IF(AND(SupplierPerformanceWorkspace[[#This Row],[On-Time %]]>=0.9,SupplierPerformanceWorkspace[[#This Row],[Average Defect Rate]]<=0.02,SupplierPerformanceWorkspace[[#This Row],[Average Delay Days]]<=2), "Preferred", IF(AND(SupplierPerformanceWorkspace[[#This Row],[On-Time %]]>=0.75,SupplierPerformanceWorkspace[[#This Row],[Average Defect Rate]]<=0.05,SupplierPerformanceWorkspace[[#This Row],[Average Delay Days]]<=5), "Acceptable", "Needs Review")) -> Needs Review
A12: S008 | B12: Metro Industrial Mart | C12: Mumbai | D12: 5 | E12: Conditional | F12: Not provided | G12: 3.2 | H12: Safety and PPE; Cleaning and Consumables | J12: S008 | K12: Metro Industrial Mart | L12: =SUMIF(PurchaseOrdersTable[[#All],[Supplier Code]],SupplierPerformanceWorkspace[[#This Row],[Supplier Code]],PurchaseOrdersTable[[#All],[Order Value (₹)]]) -> 9730568.8 | M12: =AVERAGEIF(PurchaseOrdersTable[[#All],[Supplier Code]],SupplierPerformanceWorkspace[[#This Row],[Supplier Code]],PurchaseOrdersTable[[#All],[Unit Price (₹)]]) -> 1112.0386 | N12: =AVERAGEIF(PurchaseOrdersTable[[#All],[Supplier Code]],SupplierPerformanceWorkspace[[#This Row],[Supplier Code]],PurchaseOrdersTable[[#All],[Delay Days]]) -> 4.9285714 | O12: =COUNTIFS(PurchaseOrdersTable[[#All],[Supplier Code]],SupplierPerformanceWorkspace[[#This Row],[Supplier Code]],PurchaseOrdersTable[[#All],[Delivery Status]], "On Time") /COUNTIF(PurchaseOrdersTable[[#All],[Supplier Code]],SupplierPerformanceWorkspace[[#This Row],[Supplier Code]]) -> 0 | P12: =AVERAGEIF(PurchaseOrdersTable[[#All],[Supplier Code]],SupplierPerformanceWorkspace[[#This Row],[Supplier Code]],PurchaseOrdersTable[[#All],[Defect Rate]]) -> 0.069588414 | Q12: =IF(AND(SupplierPerformanceWorkspace[[#This Row],[On-Time %]]>=0.9,SupplierPerformanceWorkspace[[#This Row],[Average Defect Rate]]<=0.02,SupplierPerformanceWorkspace[[#This Row],[Average Delay Days]]<=2), "Preferred", IF(AND(SupplierPerformanceWorkspace[[#This Row],[On-Time %]]>=0.75,SupplierPerformanceWorkspace[[#This Row],[Average Defect Rate]]<=0.05,SupplierPerformanceWorkspace[[#This Row],[Average Delay Days]]<=5), "Acceptable", "Needs Review")) -> Needs Review
A13: S009 | B13: SecureTech Safety Solutions | C13: Hyderabad | D13: 9 | E13: Approved | F13: ISO 45001 | G13: 4.3 | H13: Safety and PPE | J13: S009 | K13: SecureTech Safety Solutions | L13: =SUMIF(PurchaseOrdersTable[[#All],[Supplier Code]],SupplierPerformanceWorkspace[[#This Row],[Supplier Code]],PurchaseOrdersTable[[#All],[Order Value (₹)]]) -> 2623357.5 | M13: =AVERAGEIF(PurchaseOrdersTable[[#All],[Supplier Code]],SupplierPerformanceWorkspace[[#This Row],[Supplier Code]],PurchaseOrdersTable[[#All],[Unit Price (₹)]]) -> 399.4975 | N13: =AVERAGEIF(PurchaseOrdersTable[[#All],[Supplier Code]],SupplierPerformanceWorkspace[[#This Row],[Supplier Code]],PurchaseOrdersTable[[#All],[Delay Days]]) -> 1.5 | O13: =COUNTIFS(PurchaseOrdersTable[[#All],[Supplier Code]],SupplierPerformanceWorkspace[[#This Row],[Supplier Code]],PurchaseOrdersTable[[#All],[Delivery Status]], "On Time") /COUNTIF(PurchaseOrdersTable[[#All],[Supplier Code]],SupplierPerformanceWorkspace[[#This Row],[Supplier Code]]) -> 0.25 | P13: =AVERAGEIF(PurchaseOrdersTable[[#All],[Supplier Code]],SupplierPerformanceWorkspace[[#This Row],[Supplier Code]],PurchaseOrdersTable[[#All],[Defect Rate]]) -> 0.011041652 | Q13: =IF(AND(SupplierPerformanceWorkspace[[#This Row],[On-Time %]]>=0.9,SupplierPerformanceWorkspace[[#This Row],[Average Defect Rate]]<=0.02,SupplierPerformanceWorkspace[[#This Row],[Average Delay Days]]<=2), "Preferred", IF(AND(SupplierPerformanceWorkspace[[#This Row],[On-Time %]]>=0.75,SupplierPerformanceWorkspace[[#This Row],[Average Defect Rate]]<=0.05,SupplierPerformanceWorkspace[[#This Row],[Average Delay Days]]<=5), "Acceptable", "Needs Review")) -> Needs Review
A14: S010 | B14: CleanWorks Industrial | C14: Chennai | D14: 8 | E14: Approved | F14: ISO 9001 | G14: 4.4 | H14: Cleaning and Consumables | J14: S010 | K14: CleanWorks Industrial | L14: =SUMIF(PurchaseOrdersTable[[#All],[Supplier Code]],SupplierPerformanceWorkspace[[#This Row],[Supplier Code]],PurchaseOrdersTable[[#All],[Order Value (₹)]]) -> 2499871.7 | M14: =AVERAGEIF(PurchaseOrdersTable[[#All],[Supplier Code]],SupplierPerformanceWorkspace[[#This Row],[Supplier Code]],PurchaseOrdersTable[[#All],[Unit Price (₹)]]) -> 2276.0617 | N14: =AVERAGEIF(PurchaseOrdersTable[[#All],[Supplier Code]],SupplierPerformanceWorkspace[[#This Row],[Supplier Code]],PurchaseOrdersTable[[#All],[Delay Days]]) -> 0.83333333 | O14: =COUNTIFS(PurchaseOrdersTable[[#All],[Supplier Code]],SupplierPerformanceWorkspace[[#This Row],[Supplier Code]],PurchaseOrdersTable[[#All],[Delivery Status]], "On Time") /COUNTIF(PurchaseOrdersTable[[#All],[Supplier Code]],SupplierPerformanceWorkspace[[#This Row],[Supplier Code]]) -> 0.66666667 | P14: =AVERAGEIF(PurchaseOrdersTable[[#All],[Supplier Code]],SupplierPerformanceWorkspace[[#This Row],[Supplier Code]],PurchaseOrdersTable[[#All],[Defect Rate]]) -> 0.011423527 | Q14: =IF(AND(SupplierPerformanceWorkspace[[#This Row],[On-Time %]]>=0.9,SupplierPerformanceWorkspace[[#This Row],[Average Defect Rate]]<=0.02,SupplierPerformanceWorkspace[[#This Row],[Average Delay Days]]<=2), "Preferred", IF(AND(SupplierPerformanceWorkspace[[#This Row],[On-Time %]]>=0.75,SupplierPerformanceWorkspace[[#This Row],[Average Defect Rate]]<=0.05,SupplierPerformanceWorkspace[[#This Row],[Average Delay Days]]<=5), "Acceptable", "Needs Review")) -> Needs Review
A15: S011 | B15: Eastline Components | C15: Bhubaneswar | D15: 13 | E15: Conditional | F15: ISO 9001 | G15: 3.1 | H15: Electricals; Bearings and Mechanical | J15: S011 | K15: Eastline Components | L15: =SUMIF(PurchaseOrdersTable[[#All],[Supplier Code]],SupplierPerformanceWorkspace[[#This Row],[Supplier Code]],PurchaseOrdersTable[[#All],[Order Value (₹)]]) -> 6198284.3 | M15: =AVERAGEIF(PurchaseOrdersTable[[#All],[Supplier Code]],SupplierPerformanceWorkspace[[#This Row],[Supplier Code]],PurchaseOrdersTable[[#All],[Unit Price (₹)]]) -> 2166.9262 | N15: =AVERAGEIF(PurchaseOrdersTable[[#All],[Supplier Code]],SupplierPerformanceWorkspace[[#This Row],[Supplier Code]],PurchaseOrdersTable[[#All],[Delay Days]]) -> 6.875 | O15: =COUNTIFS(PurchaseOrdersTable[[#All],[Supplier Code]],SupplierPerformanceWorkspace[[#This Row],[Supplier Code]],PurchaseOrdersTable[[#All],[Delivery Status]], "On Time") /COUNTIF(PurchaseOrdersTable[[#All],[Supplier Code]],SupplierPerformanceWorkspace[[#This Row],[Supplier Code]]) -> 0 | P15: =AVERAGEIF(PurchaseOrdersTable[[#All],[Supplier Code]],SupplierPerformanceWorkspace[[#This Row],[Supplier Code]],PurchaseOrdersTable[[#All],[Defect Rate]]) -> 0.069565929 | Q15: =IF(AND(SupplierPerformanceWorkspace[[#This Row],[On-Time %]]>=0.9,SupplierPerformanceWorkspace[[#This Row],[Average Defect Rate]]<=0.02,SupplierPerformanceWorkspace[[#This Row],[Average Delay Days]]<=2), "Preferred", IF(AND(SupplierPerformanceWorkspace[[#This Row],[On-Time %]]>=0.75,SupplierPerformanceWorkspace[[#This Row],[Average Defect Rate]]<=0.05,SupplierPerformanceWorkspace[[#This Row],[Average Delay Days]]<=5), "Acceptable", "Needs Review")) -> Needs Review
A16: S012 | B16: ProServe MRO Solutions | C16: Jaipur | D16: 9 | E16: Approved | F16: ISO 9001 | G16: 3.8 | H16: Multiple categories | J16: S012 | K16: ProServe MRO Solutions | L16: =SUMIF(PurchaseOrdersTable[[#All],[Supplier Code]],SupplierPerformanceWorkspace[[#This Row],[Supplier Code]],PurchaseOrdersTable[[#All],[Order Value (₹)]]) -> 20271589 | M16: =AVERAGEIF(PurchaseOrdersTable[[#All],[Supplier Code]],SupplierPerformanceWorkspace[[#This Row],[Supplier Code]],PurchaseOrdersTable[[#All],[Unit Price (₹)]]) -> 2395.4374 | N16: =AVERAGEIF(PurchaseOrdersTable[[#All],[Supplier Code]],SupplierPerformanceWorkspace[[#This Row],[Supplier Code]],PurchaseOrdersTable[[#All],[Delay Days]]) -> 3.5294118 | O16: =COUNTIFS(PurchaseOrdersTable[[#All],[Supplier Code]],SupplierPerformanceWorkspace[[#This Row],[Supplier Code]],PurchaseOrdersTable[[#All],[Delivery Status]], "On Time") /COUNTIF(PurchaseOrdersTable[[#All],[Supplier Code]],SupplierPerformanceWorkspace[[#This Row],[Supplier Code]]) -> 0.029411765 | P16: =AVERAGEIF(PurchaseOrdersTable[[#All],[Supplier Code]],SupplierPerformanceWorkspace[[#This Row],[Supplier Code]],PurchaseOrdersTable[[#All],[Defect Rate]]) -> 0.027961972 | Q16: =IF(AND(SupplierPerformanceWorkspace[[#This Row],[On-Time %]]>=0.9,SupplierPerformanceWorkspace[[#This Row],[Average Defect Rate]]<=0.02,SupplierPerformanceWorkspace[[#This Row],[Average Delay Days]]<=2), "Preferred", IF(AND(SupplierPerformanceWorkspace[[#This Row],[On-Time %]]>=0.75,SupplierPerformanceWorkspace[[#This Row],[Average Defect Rate]]<=0.05,SupplierPerformanceWorkspace[[#This Row],[Average Delay Days]]<=5), "Acceptable", "Needs Review")) -> Needs Review

Sheet 03_Product_Master
A1: Product Master and Category Workspace | H1: Category Analysis Workspace | M1: HOW TO USE THIS SHEET
A2: Use Product Code to connect purchase-order records with the correct product and category.
M3: 1. Use the product master to complete Product Name and Category in 01_Purchase_Orders. 2. Complete the Category Analysis Workspace using the purchase-order data. 3. Identify the highest-spend category. 4. Create a chart showing total spend by category. 5. Use the highest-spend category as the focus for the supplier comparison.
A4: Product Code | B4: Product Name | C4: Category | D4: Unit | E4: Criticality | F4: Reference Price (₹) | H4: Category | I4: Total Spend | J4: Number of Orders | K4: Average Unit Price
A5: PPE-001 | B5: Industrial Safety Helmet | C5: Safety and PPE | D5: Each | E5: High | F5: 450 | H5: Safety and PPE | I5: =SUMIF(PurchaseOrdersTable[[#All],[Category]],CategoryAnalysisWorkspace[[#This Row],[Category]],PurchaseOrdersTable[[#All],[Order Value (₹)]]) -> 29769140 | J5: =COUNTIF(PurchaseOrdersTable[[#All],[Category]],CategoryAnalysisWorkspace[[#This Row],[Category]]) -> 36 | K5: =AVERAGEIF(PurchaseOrdersTable[[#All],[Category]],CategoryAnalysisWorkspace[[#This Row],[Category]],PurchaseOrdersTable[[#All],[Unit Price (₹)]]) -> 472.22667
A6: PPE-002 | B6: Nitrile Gloves - Box of 100 | C6: Safety and PPE | D6: Box | E6: Medium | F6: 780 | H6: Electricals | I6: =SUMIF(PurchaseOrdersTable[[#All],[Category]],CategoryAnalysisWorkspace[[#This Row],[Category]],PurchaseOrdersTable[[#All],[Order Value (₹)]]) -> 23606089 | J6: =COUNTIF(PurchaseOrdersTable[[#All],[Category]],CategoryAnalysisWorkspace[[#This Row],[Category]]) -> 24 | K6: =AVERAGEIF(PurchaseOrdersTable[[#All],[Category]],CategoryAnalysisWorkspace[[#This Row],[Category]],PurchaseOrdersTable[[#All],[Unit Price (₹)]]) -> 2222.4504
A7: PPE-003 | B7: Safety Goggles | C7: Safety and PPE | D7: Each | E7: High | F7: 320 | H7: Hand Tools | I7: =SUMIF(PurchaseOrdersTable[[#All],[Category]],CategoryAnalysisWorkspace[[#This Row],[Category]],PurchaseOrdersTable[[#All],[Order Value (₹)]]) -> 8568624.4 | J7: =COUNTIF(PurchaseOrdersTable[[#All],[Category]],CategoryAnalysisWorkspace[[#This Row],[Category]]) -> 18 | K7: =AVERAGEIF(PurchaseOrdersTable[[#All],[Category]],CategoryAnalysisWorkspace[[#This Row],[Category]],PurchaseOrdersTable[[#All],[Unit Price (₹)]]) -> 4883.2978
A8: PPE-004 | B8: Reflective Safety Jacket | C8: Safety and PPE | D8: Each | E8: Medium | F8: 550 | H8: Bearings and Mechanical | I8: =SUMIF(PurchaseOrdersTable[[#All],[Category]],CategoryAnalysisWorkspace[[#This Row],[Category]],PurchaseOrdersTable[[#All],[Order Value (₹)]]) -> 17594926 | J8: =COUNTIF(PurchaseOrdersTable[[#All],[Category]],CategoryAnalysisWorkspace[[#This Row],[Category]]) -> 24 | K8: =AVERAGEIF(PurchaseOrdersTable[[#All],[Category]],CategoryAnalysisWorkspace[[#This Row],[Category]],PurchaseOrdersTable[[#All],[Unit Price (₹)]]) -> 1858.1862
A9: ELE-001 | B9: Miniature Circuit Breaker 32A | C9: Electricals | D9: Each | E9: High | F9: 625 | H9: Cleaning and Consumables | I9: =SUMIF(PurchaseOrdersTable[[#All],[Category]],CategoryAnalysisWorkspace[[#This Row],[Category]],PurchaseOrdersTable[[#All],[Order Value (₹)]]) -> 8178021.4 | J9: =COUNTIF(PurchaseOrdersTable[[#All],[Category]],CategoryAnalysisWorkspace[[#This Row],[Category]]) -> 18 | K9: =AVERAGEIF(PurchaseOrdersTable[[#All],[Category]],CategoryAnalysisWorkspace[[#This Row],[Category]],PurchaseOrdersTable[[#All],[Unit Price (₹)]]) -> 2343.6672
A10: ELE-002 | B10: Copper Cable Roll - 100 m | C10: Electricals | D10: Roll | E10: High | F10: 4200
A11: ELE-003 | B11: Three-Phase Contactor | C11: Electricals | D11: Each | E11: High | F11: 2250
A12: ELE-004 | B12: Industrial LED High-Bay Light | C12: Electricals | D12: Each | E12: Medium | F12: 1850 | H12: Highest spend category is Safety & PPE
A13: TOOL-001 | B13: Industrial Angle Grinder | C13: Hand Tools | D13: Each | E13: Medium | F13: 3850
A14: TOOL-002 | B14: Industrial Torque Wrench | C14: Hand Tools | D14: Each | E14: Medium | F14: 4850
A15: TOOL-003 | B15: Heavy-Duty Drill Machine | C15: Hand Tools | D15: Each | E15: High | F15: 6200
A16: BRG-001 | B16: Deep-Groove Ball Bearing | C16: Bearings and Mechanical | D16: Each | E16: High | F16: 1250
A17: BRG-002 | B17: Industrial Roller Bearing | C17: Bearings and Mechanical | D17: Each | E17: High | F17: 2950
A18: BRG-003 | B18: Heavy-Duty Industrial Belt | C18: Bearings and Mechanical | D18: Each | E18: Medium | F18: 1450
A19: CLN-001 | B19: Industrial Degreaser - 20 L | C19: Cleaning and Consumables | D19: Can | E19: Medium | F19: 3100
A20: CLN-002 | B20: Chemical Absorbent Pads - Pack | C20: Cleaning and Consumables | D20: Pack | E20: Medium | F20: 1650
A21: CLN-003 | B21: Industrial Wipes - Carton | C21: Cleaning and Consumables | D21: Carton | E21: Low | F21: 950
A22: CLN-004 | B22: Multipurpose Lubricant - Drum | C22: Cleaning and Consumables | D22: Drum | E22: High | F22: 5400

Sheet 04_Rates_and_Rules
A1: Regional Charges and Supplier Classification Rules | G1: USING THE RATES AND RULES
A2: The regional charge table is horizontal so that it can be used as a reference during the sourcing decision.
G3: Regional charges: • Match the destination region across the top row. • Use Standard Freight for routine delivery and Express Freight for urgent delivery. • Freight Cost is the higher of the percentage-based freight and the minimum freight charge. • Add the fixed Handling Charge after freight. Supplier classification: A supplier should meet all Preferred conditions to be classified Preferred. If it fails Preferred but meets all Acceptable conditions, classify it Acceptable. Otherwise classify it Needs Review. Delivery status: Use Delay Days to classify each order.
A4: Charge | B4: North | C4: West | D4: South | E4: East
A5: Standard Freight Rate | B5: 0.022 | C5: 0.025 | D5: 0.028 | E5: 0.03
A6: Express Freight Rate | B6: 0.045 | C6: 0.048 | D6: 0.05 | E6: 0.052
A7: Handling Charge | B7: 3500 | C7: 4200 | D7: 4500 | E7: 4000
A8: Minimum Freight Charge | B8: 12000 | C8: 15000 | D8: 15000 | E8: 14000
A11: Supplier Performance Classification
A12: Classification | B12: On-Time Delivery | C12: Average Defect Rate | D12: Average Delay | E12: Interpretation
A13: Preferred | B13: At least 90% | C13: Not more than 2% | D13: Not more than 2 days | E13: Strong overall performance
A14: Acceptable | B14: At least 75% | C14: Not more than 5% | D14: Not more than 5 days | E14: Usable with routine monitoring
A15: Needs Review | B15: Below acceptable threshold | C15: Above 5% | D15: Above 5 days | E15: Management review required
A18: Order Delivery Status Rules
A19: Status | B19: Delay Days | C19: Meaning
A20: On Time | B20: 0 or fewer | C20: Delivered by the promised date
A21: Slightly Late | B21: 1 to 3 | C21: Short delay requiring monitoring
A22: Seriously Late | B22: More than 3 | C22: Material delivery failure

Sheet 05_Sourcing_Decision
A1: Sourcing Decision: Industrial Safety Helmet Order | S1: SOURCING DECISION STEPS
A2: Use historical supplier performance, current quotations, regional charges and the approved budget to recommend a primary and backup supplier.
